<?xml version="1.0"?>
<robot xmlns:xacro="https://www.ros.org/wiki/xacro">

    <xacro:include filename="inertial_macros.xacro"/>
    

    <!-- MATERIALS-->

    <material name="red">
        <color rgba="1 0.0 0.0 1.0"/>
    </material>

    <material name="black">
        <color rgba="0.0 0.0 0.0 1.0"/>
    </material>

    <!-- LINKS-->

    <link name="base_link"></link>

    <link name="chassis">
        <visual>
            <geometry>
                <box size="0.4 0.25 0.285"/>
            </geometry>
            <origin xyz="0.2 0.0 0.1425" rpy="0.0 0.0 0.0"/>
            <material name="red"/>
        </visual>
        <collision>
            <geometry>
                <box size="0.4 0.25 0.285"/>
            </geometry>
            <origin xyz="0.2 0.0 0.1425" rpy="0.0 0.0 0.0"/>
        </collision>
        <xacro:inertial_box mass="0.5" x="0.4" y="0.25" z="0.285">
            <origin xyz="0.2 0.0 0.1425" rpy="0.0 0.0 0.0"/>
        </xacro:inertial_box>
    </link>
    <gazebo reference="chassis">
        <material>
            Gazebo/Red
        </material>
    </gazebo>
    


    <link name="left_wheel">
        <visual>
            <geometry>
                <cylinder radius="0.055" length="0.04"/>
            </geometry>
            <material name="black"/>
        </visual>
        <collision>
            <geometry>
                <cylinder radius="0.055" length="0.04"/>
            </geometry>
            <material name="black"/>
        </collision>
        <xacro:inertial_cylinder mass="0.1" length="0.04" radius="0.055">
            <origin xyz="0.0 0.0 0.0" rpy="0.0 0.0 0.0"/>
        </xacro:inertial_cylinder>
    </link>
    <gazebo reference="left_wheel">
        <material>
            Gazebo/Black
        </material>
    </gazebo>   


    <link name="right_wheel">
        <visual>
            <geometry>
                <cylinder radius="0.055" length="0.04"/>
            </geometry>
            <material name="black"/>
        </visual>
        <collision>
            <geometry>
                <cylinder radius="0.055" length="0.04"/>
            </geometry>
            <material name="black"/>
        </collision>
        <xacro:inertial_cylinder mass="0.1" length="0.04" radius="0.055">
            <origin xyz="0.0 0.0 0.0" rpy="0.0 0.0 0.0"/>
        </xacro:inertial_cylinder>
    </link>
    <gazebo reference="right_wheel">
        <material>
            Gazebo/Black
        </material>
    </gazebo> 

    <link name="back_left_wheel">
        <visual>
            <geometry>
                <cylinder radius="0.055" length="0.04"/>
            </geometry>
            <material name="black"/>
        </visual>
        <collision>
            <geometry>
                <cylinder radius="0.055" length="0.04"/>
            </geometry>
            <material name="black"/>
        </collision>
        <xacro:inertial_cylinder mass="0.1" length="0.04" radius="0.055">
            <origin xyz="0.0 0.0 0.0" rpy="0.0 0.0 0.0"/>
        </xacro:inertial_cylinder>
    </link>
    <gazebo reference="back_left_wheel">
        <material>
            Gazebo/Black
        </material>
    </gazebo> 

    <link name="back_right_wheel">
        <visual>
            <geometry>
                <cylinder radius="0.055" length="0.04"/>
            </geometry>
            <material name="black"/>
        </visual>
        <collision>
            <geometry>
                <cylinder radius="0.055" length="0.04"/>
            </geometry>
            <material name="black"/>
        </collision>
        <xacro:inertial_cylinder mass="0.1" length="0.04" radius="0.055">
            <origin xyz="0.0 0.0 0.0" rpy="0.0 0.0 0.0"/>
        </xacro:inertial_cylinder>
    </link>
    <gazebo reference="back_right_wheel">
        <material>
            Gazebo/Black
        </material>
    </gazebo> 


    <!-- JOINTS-->

    <joint name="chassis_joint" type="fixed">
        <parent link="base_link"/>
        <child link="chassis"/>
        <origin xyz="-0.2 0.0 0.0" rpy="0.0 0.0 0.0"/>
    </joint>

    <joint name="left_wheel_joint" type="continuous">
        <parent link="chassis"/>
        <child link="left_wheel"/>
        <axis xyz="0.0 0.0 1"/>
        <origin xyz="0.323 0.18 0.0" rpy="-${pi/2} 0.0 0.0"/>
    </joint>

    <joint name="right_wheel_joint" type="continuous">
        <parent link="chassis"/>
        <child link="right_wheel"/>
        <axis xyz="0.0 0.0 1"/>
        <origin xyz="0.323 -0.18 0.0" rpy="-${pi/2} 0.0 0.0"/>
    </joint>

    <joint name="back_left_wheel_joint" type="continuous">
        <parent link="chassis"/>
        <child link="back_left_wheel"/>
        <axis xyz="0.0 0.0 1"/>
        <origin xyz="0.08 0.18 0.0" rpy="-${pi/2} 0.0 0.0"/>
    </joint>

    <joint name="back_right_wheel_joint" type="continuous">
        <parent link="chassis"/>
        <child link="back_right_wheel"/>
        <axis xyz="0.0 0.0 1"/>
        <origin xyz="0.08 -0.18 0.0" rpy="-${pi/2} 0.0 0.0"/>
    </joint>
    
</robot>